commit 4b15b25f400335b6e2820cb690430324748372f9
Author: nicksantos@google.com <nicksantos@google.com@b0f006be-c8cd-11de-a2e8-8d36a3108c74>
Date:   Tue Jul 24 17:04:32 2012

    when handling a finally block like so,
    try { alert(1) } finally { }
    There needs to be 2 edges: an unconditional edge to the statement
    after the 'finally', and an edge for the code path that continues
    handling the exception. Label the second edge with ON_EX instead of UNCOND.
    Fixes issue 779
    
    R=acleung
    DELTA=18  (14 added, 0 deleted, 4 changed)
    
    
    Revision created by MOE tool push_codebase.
    MOE_MIGRATION=5214
    
    
    git-svn-id: https://closure-compiler.googlecode.com/svn/trunk@2101 b0f006be-c8cd-11de-a2e8-8d36a3108c74

diff --git a/test/com/google/javascript/jscomp/CheckMissingReturnTest.java b/test/com/google/javascript/jscomp/CheckMissingReturnTest.java
--- a/test/com/google/javascript/jscomp/CheckMissingReturnTest.java
+++ b/test/com/google/javascript/jscomp/CheckMissingReturnTest.java
@@ -194,0 +194,6 @@
+  public void testIssue779() {
+    testNotMissing(
+        "var a = f(); try { alert(); if (a > 0) return 1; }" +
+        "finally { a = 5; } return 2;");
+  }
+
